[2025-01-28 17:30:39,813][flwr][WARNING] - Both server and strategy were provided, ignoring strategy
[2025-01-28 17:30:39,815][flwr][INFO] - Starting Flower simulation, config: num_rounds=2, no round_timeout
[2025-01-28 17:30:53,934][flwr][INFO] - Flower VCE: Ray initialized with resources: {'CPU': 8.0, 'node:__internal_head__': 1.0, 'node:127.0.0.1': 1.0, 'memory': 576552960.0, 'object_store_memory': 288276480.0}
[2025-01-28 17:30:53,935][flwr][INFO] - Optimize your simulation with Flower VCE: https://flower.ai/docs/framework/how-to-run-simulations.html
[2025-01-28 17:30:53,937][flwr][INFO] - Flower VCE: Resources for each Virtual Client: {'num_cpus': 4, 'num_gpus': 0.0}
[2025-01-28 17:30:53,987][flwr][INFO] - Flower VCE: Creating VirtualClientEngineActorPool with 2 actors
[2025-01-28 17:30:53,990][flwr][INFO] - [INIT]
[2025-01-28 17:30:53,991][flwr][INFO] - Requesting initial parameters from one random client
[2025-01-28 17:31:00,490][flwr][INFO] - Received initial parameters from one random client
[2025-01-28 17:31:00,491][flwr][INFO] - Starting evaluation of initial global parameters
[2025-01-28 17:31:00,561][flwr][INFO] - initial parameters (loss, other metrics): 0.6931511589459011, {'accuracy': 0.5073170731707317, 'f1-score': 0.3447785934170022}
[2025-01-28 17:31:00,562][flwr][INFO] - 
[2025-01-28 17:31:00,563][flwr][INFO] - [ROUND 1]
[2025-01-28 17:31:00,564][flwr][INFO] - configure_fit: strategy sampled 7 clients (out of 7)
[2025-01-28 17:31:09,298][flwr][ERROR] - Traceback (most recent call last):
  File "C:\Users\Riccardo\miniconda3\envs\flower\Lib\site-packages\flwr\simulation\ray_transport\ray_client_proxy.py", line 94, in _submit_job
    out_mssg, updated_context = self.actor_pool.get_client_result(
                                ^^^^^^^^^^^^^^^^^^^^^^^^^^^^^^^^^^
  File "C:\Users\Riccardo\miniconda3\envs\flower\Lib\site-packages\flwr\simulation\ray_transport\ray_actor.py", line 398, in get_client_result
    return self._fetch_future_result(cid)
           ^^^^^^^^^^^^^^^^^^^^^^^^^^^^^^
  File "C:\Users\Riccardo\miniconda3\envs\flower\Lib\site-packages\flwr\simulation\ray_transport\ray_actor.py", line 279, in _fetch_future_result
    res_cid, out_mssg, updated_context = ray.get(
                                         ^^^^^^^^
  File "C:\Users\Riccardo\miniconda3\envs\flower\Lib\site-packages\ray\_private\auto_init_hook.py", line 21, in auto_init_wrapper
    return fn(*args, **kwargs)
           ^^^^^^^^^^^^^^^^^^^
  File "C:\Users\Riccardo\miniconda3\envs\flower\Lib\site-packages\ray\_private\client_mode_hook.py", line 103, in wrapper
    return func(*args, **kwargs)
           ^^^^^^^^^^^^^^^^^^^^^
  File "C:\Users\Riccardo\miniconda3\envs\flower\Lib\site-packages\ray\_private\worker.py", line 2691, in get
    values, debugger_breakpoint = worker.get_objects(object_refs, timeout=timeout)
                                  ^^^^^^^^^^^^^^^^^^^^^^^^^^^^^^^^^^^^^^^^^^^^^^^^
  File "C:\Users\Riccardo\miniconda3\envs\flower\Lib\site-packages\ray\_private\worker.py", line 871, in get_objects
    raise value.as_instanceof_cause()
ray.exceptions.RayTaskError(ClientAppException): [36mray::ClientAppActor.run()[39m (pid=14432, ip=127.0.0.1, actor_id=39da8d751a7e8f865854042a01000000, repr=<flwr.simulation.ray_transport.ray_actor.ClientAppActor object at 0x000001AE6AB49050>)
                  ^^^^^^^^^^^^^^^^^^^^^^^^^^^^^^^^^^^^^
  File "C:\Users\Riccardo\miniconda3\envs\flower\Lib\site-packages\flwr\client\client_app.py", line 143, in __call__
    return self._call(message, context)
           ^^^^^^^^^^^^^^^^^^^^^^^^^^^^
  File "C:\Users\Riccardo\miniconda3\envs\flower\Lib\site-packages\flwr\client\client_app.py", line 126, in ffn
    out_message = handle_legacy_message_from_msgtype(
                  ^^^^^^^^^^^^^^^^^^^^^^^^^^^^^^^^^^^
  File "C:\Users\Riccardo\miniconda3\envs\flower\Lib\site-packages\flwr\client\message_handler\message_handler.py", line 95, in handle_legacy_message_from_msgtype
    client = client_fn(context)
             ^^^^^^^^^^^^^^^^^^
  File "C:\Users\Riccardo\miniconda3\envs\flower\Lib\site-packages\flwr\client\client_app.py", line 67, in adaptor_fn
    return client_fn(str(cid))  # type: ignore
           ^^^^^^^^^^^^^^^^^^^
  File "c:\Users\Riccardo\Desktop\PoliMi\Tesi-Francesco\clients\multiclass\client_fedavg.py", line 120, in client_fn
    trainloader = trainloaders[int(cid)]
                  ~~~~~~~~~~~~^^^^^^^^^^
IndexError: list index out of range

The above exception was the direct cause of the following exception:

[36mray::ClientAppActor.run()[39m (pid=14432, ip=127.0.0.1, actor_id=39da8d751a7e8f865854042a01000000, repr=<flwr.simulation.ray_transport.ray_actor.ClientAppActor object at 0x000001AE6AB49050>)
  File "python\ray\_raylet.pyx", line 1853, in ray._raylet.execute_task
  File "python\ray\_raylet.pyx", line 1954, in ray._raylet.execute_task
  File "python\ray\_raylet.pyx", line 1859, in ray._raylet.execute_task
  File "python\ray\_raylet.pyx", line 1800, in ray._raylet.execute_task.function_executor
  File "C:\Users\Riccardo\miniconda3\envs\flower\Lib\site-packages\ray\_private\function_manager.py", line 696, in actor_method_executor
    return method(__ray_actor, *args, **kwargs)
           ^^^^^^^^^^^^^^^^^^^^^^^^^^^^^^^^^^^^
  File "C:\Users\Riccardo\miniconda3\envs\flower\Lib\site-packages\ray\util\tracing\tracing_helper.py", line 467, in _resume_span
    return method(self, *_args, **_kwargs)
           ^^^^^^^^^^^^^^^^^^^^^^^^^^^^^^^
  File "C:\Users\Riccardo\miniconda3\envs\flower\Lib\site-packages\flwr\simulation\ray_transport\ray_actor.py", line 63, in run
    raise ClientAppException(str(ex)) from ex
flwr.client.client_app.ClientAppException: 
Exception ClientAppException occurred. Message: list index out of range

[2025-01-28 17:31:09,325][flwr][ERROR] - [36mray::ClientAppActor.run()[39m (pid=14432, ip=127.0.0.1, actor_id=39da8d751a7e8f865854042a01000000, repr=<flwr.simulation.ray_transport.ray_actor.ClientAppActor object at 0x000001AE6AB49050>)
                  ^^^^^^^^^^^^^^^^^^^^^^^^^^^^^^^^^^^^^
  File "C:\Users\Riccardo\miniconda3\envs\flower\Lib\site-packages\flwr\client\client_app.py", line 143, in __call__
    return self._call(message, context)
           ^^^^^^^^^^^^^^^^^^^^^^^^^^^^
  File "C:\Users\Riccardo\miniconda3\envs\flower\Lib\site-packages\flwr\client\client_app.py", line 126, in ffn
    out_message = handle_legacy_message_from_msgtype(
                  ^^^^^^^^^^^^^^^^^^^^^^^^^^^^^^^^^^^
  File "C:\Users\Riccardo\miniconda3\envs\flower\Lib\site-packages\flwr\client\message_handler\message_handler.py", line 95, in handle_legacy_message_from_msgtype
    client = client_fn(context)
             ^^^^^^^^^^^^^^^^^^
  File "C:\Users\Riccardo\miniconda3\envs\flower\Lib\site-packages\flwr\client\client_app.py", line 67, in adaptor_fn
    return client_fn(str(cid))  # type: ignore
           ^^^^^^^^^^^^^^^^^^^
  File "c:\Users\Riccardo\Desktop\PoliMi\Tesi-Francesco\clients\multiclass\client_fedavg.py", line 120, in client_fn
    trainloader = trainloaders[int(cid)]
                  ~~~~~~~~~~~~^^^^^^^^^^
IndexError: list index out of range

The above exception was the direct cause of the following exception:

[36mray::ClientAppActor.run()[39m (pid=14432, ip=127.0.0.1, actor_id=39da8d751a7e8f865854042a01000000, repr=<flwr.simulation.ray_transport.ray_actor.ClientAppActor object at 0x000001AE6AB49050>)
  File "python\ray\_raylet.pyx", line 1853, in ray._raylet.execute_task
  File "python\ray\_raylet.pyx", line 1954, in ray._raylet.execute_task
  File "python\ray\_raylet.pyx", line 1859, in ray._raylet.execute_task
  File "python\ray\_raylet.pyx", line 1800, in ray._raylet.execute_task.function_executor
  File "C:\Users\Riccardo\miniconda3\envs\flower\Lib\site-packages\ray\_private\function_manager.py", line 696, in actor_method_executor
    return method(__ray_actor, *args, **kwargs)
           ^^^^^^^^^^^^^^^^^^^^^^^^^^^^^^^^^^^^
  File "C:\Users\Riccardo\miniconda3\envs\flower\Lib\site-packages\ray\util\tracing\tracing_helper.py", line 467, in _resume_span
    return method(self, *_args, **_kwargs)
           ^^^^^^^^^^^^^^^^^^^^^^^^^^^^^^^
  File "C:\Users\Riccardo\miniconda3\envs\flower\Lib\site-packages\flwr\simulation\ray_transport\ray_actor.py", line 63, in run
    raise ClientAppException(str(ex)) from ex
flwr.client.client_app.ClientAppException: 
Exception ClientAppException occurred. Message: list index out of range
[2025-01-28 17:31:15,857][flwr][ERROR] - Traceback (most recent call last):
  File "C:\Users\Riccardo\miniconda3\envs\flower\Lib\site-packages\flwr\simulation\ray_transport\ray_client_proxy.py", line 94, in _submit_job
    out_mssg, updated_context = self.actor_pool.get_client_result(
                                ^^^^^^^^^^^^^^^^^^^^^^^^^^^^^^^^^^
  File "C:\Users\Riccardo\miniconda3\envs\flower\Lib\site-packages\flwr\simulation\ray_transport\ray_actor.py", line 398, in get_client_result
    return self._fetch_future_result(cid)
           ^^^^^^^^^^^^^^^^^^^^^^^^^^^^^^
  File "C:\Users\Riccardo\miniconda3\envs\flower\Lib\site-packages\flwr\simulation\ray_transport\ray_actor.py", line 279, in _fetch_future_result
    res_cid, out_mssg, updated_context = ray.get(
                                         ^^^^^^^^
  File "C:\Users\Riccardo\miniconda3\envs\flower\Lib\site-packages\ray\_private\auto_init_hook.py", line 21, in auto_init_wrapper
    return fn(*args, **kwargs)
           ^^^^^^^^^^^^^^^^^^^
  File "C:\Users\Riccardo\miniconda3\envs\flower\Lib\site-packages\ray\_private\client_mode_hook.py", line 103, in wrapper
    return func(*args, **kwargs)
           ^^^^^^^^^^^^^^^^^^^^^
  File "C:\Users\Riccardo\miniconda3\envs\flower\Lib\site-packages\ray\_private\worker.py", line 2691, in get
    values, debugger_breakpoint = worker.get_objects(object_refs, timeout=timeout)
                                  ^^^^^^^^^^^^^^^^^^^^^^^^^^^^^^^^^^^^^^^^^^^^^^^^
  File "C:\Users\Riccardo\miniconda3\envs\flower\Lib\site-packages\ray\_private\worker.py", line 871, in get_objects
    raise value.as_instanceof_cause()
ray.exceptions.RayTaskError(ClientAppException): [36mray::ClientAppActor.run()[39m (pid=22472, ip=127.0.0.1, actor_id=c11cc626da41c49edd4531c801000000, repr=<flwr.simulation.ray_transport.ray_actor.ClientAppActor object at 0x000001F87F9A1050>)
                  ^^^^^^^^^^^^^^^^^^^^^^^^^^^^^^^^^^^^^
  File "C:\Users\Riccardo\miniconda3\envs\flower\Lib\site-packages\flwr\client\client_app.py", line 143, in __call__
    return self._call(message, context)
           ^^^^^^^^^^^^^^^^^^^^^^^^^^^^
  File "C:\Users\Riccardo\miniconda3\envs\flower\Lib\site-packages\flwr\client\client_app.py", line 126, in ffn
    out_message = handle_legacy_message_from_msgtype(
                  ^^^^^^^^^^^^^^^^^^^^^^^^^^^^^^^^^^^
  File "C:\Users\Riccardo\miniconda3\envs\flower\Lib\site-packages\flwr\client\message_handler\message_handler.py", line 95, in handle_legacy_message_from_msgtype
    client = client_fn(context)
             ^^^^^^^^^^^^^^^^^^
  File "C:\Users\Riccardo\miniconda3\envs\flower\Lib\site-packages\flwr\client\client_app.py", line 67, in adaptor_fn
    return client_fn(str(cid))  # type: ignore
           ^^^^^^^^^^^^^^^^^^^
  File "c:\Users\Riccardo\Desktop\PoliMi\Tesi-Francesco\clients\multiclass\client_fedavg.py", line 120, in client_fn
    trainloader = trainloaders[int(cid)]
                  ~~~~~~~~~~~~^^^^^^^^^^
IndexError: list index out of range

The above exception was the direct cause of the following exception:

[36mray::ClientAppActor.run()[39m (pid=22472, ip=127.0.0.1, actor_id=c11cc626da41c49edd4531c801000000, repr=<flwr.simulation.ray_transport.ray_actor.ClientAppActor object at 0x000001F87F9A1050>)
  File "python\ray\_raylet.pyx", line 1853, in ray._raylet.execute_task
  File "python\ray\_raylet.pyx", line 1954, in ray._raylet.execute_task
  File "python\ray\_raylet.pyx", line 1859, in ray._raylet.execute_task
  File "python\ray\_raylet.pyx", line 1800, in ray._raylet.execute_task.function_executor
  File "C:\Users\Riccardo\miniconda3\envs\flower\Lib\site-packages\ray\_private\function_manager.py", line 696, in actor_method_executor
    return method(__ray_actor, *args, **kwargs)
           ^^^^^^^^^^^^^^^^^^^^^^^^^^^^^^^^^^^^
  File "C:\Users\Riccardo\miniconda3\envs\flower\Lib\site-packages\ray\util\tracing\tracing_helper.py", line 467, in _resume_span
    return method(self, *_args, **_kwargs)
           ^^^^^^^^^^^^^^^^^^^^^^^^^^^^^^^
  File "C:\Users\Riccardo\miniconda3\envs\flower\Lib\site-packages\flwr\simulation\ray_transport\ray_actor.py", line 63, in run
    raise ClientAppException(str(ex)) from ex
flwr.client.client_app.ClientAppException: 
Exception ClientAppException occurred. Message: list index out of range

[2025-01-28 17:31:15,890][flwr][ERROR] - [36mray::ClientAppActor.run()[39m (pid=22472, ip=127.0.0.1, actor_id=c11cc626da41c49edd4531c801000000, repr=<flwr.simulation.ray_transport.ray_actor.ClientAppActor object at 0x000001F87F9A1050>)
                  ^^^^^^^^^^^^^^^^^^^^^^^^^^^^^^^^^^^^^
  File "C:\Users\Riccardo\miniconda3\envs\flower\Lib\site-packages\flwr\client\client_app.py", line 143, in __call__
    return self._call(message, context)
           ^^^^^^^^^^^^^^^^^^^^^^^^^^^^
  File "C:\Users\Riccardo\miniconda3\envs\flower\Lib\site-packages\flwr\client\client_app.py", line 126, in ffn
    out_message = handle_legacy_message_from_msgtype(
                  ^^^^^^^^^^^^^^^^^^^^^^^^^^^^^^^^^^^
  File "C:\Users\Riccardo\miniconda3\envs\flower\Lib\site-packages\flwr\client\message_handler\message_handler.py", line 95, in handle_legacy_message_from_msgtype
    client = client_fn(context)
             ^^^^^^^^^^^^^^^^^^
  File "C:\Users\Riccardo\miniconda3\envs\flower\Lib\site-packages\flwr\client\client_app.py", line 67, in adaptor_fn
    return client_fn(str(cid))  # type: ignore
           ^^^^^^^^^^^^^^^^^^^
  File "c:\Users\Riccardo\Desktop\PoliMi\Tesi-Francesco\clients\multiclass\client_fedavg.py", line 120, in client_fn
    trainloader = trainloaders[int(cid)]
                  ~~~~~~~~~~~~^^^^^^^^^^
IndexError: list index out of range

The above exception was the direct cause of the following exception:

[36mray::ClientAppActor.run()[39m (pid=22472, ip=127.0.0.1, actor_id=c11cc626da41c49edd4531c801000000, repr=<flwr.simulation.ray_transport.ray_actor.ClientAppActor object at 0x000001F87F9A1050>)
  File "python\ray\_raylet.pyx", line 1853, in ray._raylet.execute_task
  File "python\ray\_raylet.pyx", line 1954, in ray._raylet.execute_task
  File "python\ray\_raylet.pyx", line 1859, in ray._raylet.execute_task
  File "python\ray\_raylet.pyx", line 1800, in ray._raylet.execute_task.function_executor
  File "C:\Users\Riccardo\miniconda3\envs\flower\Lib\site-packages\ray\_private\function_manager.py", line 696, in actor_method_executor
    return method(__ray_actor, *args, **kwargs)
           ^^^^^^^^^^^^^^^^^^^^^^^^^^^^^^^^^^^^
  File "C:\Users\Riccardo\miniconda3\envs\flower\Lib\site-packages\ray\util\tracing\tracing_helper.py", line 467, in _resume_span
    return method(self, *_args, **_kwargs)
           ^^^^^^^^^^^^^^^^^^^^^^^^^^^^^^^
  File "C:\Users\Riccardo\miniconda3\envs\flower\Lib\site-packages\flwr\simulation\ray_transport\ray_actor.py", line 63, in run
    raise ClientAppException(str(ex)) from ex
flwr.client.client_app.ClientAppException: 
Exception ClientAppException occurred. Message: list index out of range
[2025-01-28 17:31:29,844][flwr][ERROR] - Traceback (most recent call last):
  File "C:\Users\Riccardo\miniconda3\envs\flower\Lib\site-packages\flwr\simulation\ray_transport\ray_client_proxy.py", line 94, in _submit_job
    out_mssg, updated_context = self.actor_pool.get_client_result(
                                ^^^^^^^^^^^^^^^^^^^^^^^^^^^^^^^^^^
  File "C:\Users\Riccardo\miniconda3\envs\flower\Lib\site-packages\flwr\simulation\ray_transport\ray_actor.py", line 398, in get_client_result
    return self._fetch_future_result(cid)
           ^^^^^^^^^^^^^^^^^^^^^^^^^^^^^^
  File "C:\Users\Riccardo\miniconda3\envs\flower\Lib\site-packages\flwr\simulation\ray_transport\ray_actor.py", line 279, in _fetch_future_result
    res_cid, out_mssg, updated_context = ray.get(
                                         ^^^^^^^^
  File "C:\Users\Riccardo\miniconda3\envs\flower\Lib\site-packages\ray\_private\auto_init_hook.py", line 21, in auto_init_wrapper
    return fn(*args, **kwargs)
           ^^^^^^^^^^^^^^^^^^^
  File "C:\Users\Riccardo\miniconda3\envs\flower\Lib\site-packages\ray\_private\client_mode_hook.py", line 103, in wrapper
    return func(*args, **kwargs)
           ^^^^^^^^^^^^^^^^^^^^^
  File "C:\Users\Riccardo\miniconda3\envs\flower\Lib\site-packages\ray\_private\worker.py", line 2691, in get
    values, debugger_breakpoint = worker.get_objects(object_refs, timeout=timeout)
                                  ^^^^^^^^^^^^^^^^^^^^^^^^^^^^^^^^^^^^^^^^^^^^^^^^
  File "C:\Users\Riccardo\miniconda3\envs\flower\Lib\site-packages\ray\_private\worker.py", line 871, in get_objects
    raise value.as_instanceof_cause()
ray.exceptions.RayTaskError(ClientAppException): [36mray::ClientAppActor.run()[39m (pid=22472, ip=127.0.0.1, actor_id=c11cc626da41c49edd4531c801000000, repr=<flwr.simulation.ray_transport.ray_actor.ClientAppActor object at 0x000001F87F9A1050>)
                  ^^^^^^^^^^^^^^^^^^^^^^^^^^^^^^^^^^^^^
  File "C:\Users\Riccardo\miniconda3\envs\flower\Lib\site-packages\flwr\client\client_app.py", line 143, in __call__
    return self._call(message, context)
           ^^^^^^^^^^^^^^^^^^^^^^^^^^^^
  File "C:\Users\Riccardo\miniconda3\envs\flower\Lib\site-packages\flwr\client\client_app.py", line 126, in ffn
    out_message = handle_legacy_message_from_msgtype(
                  ^^^^^^^^^^^^^^^^^^^^^^^^^^^^^^^^^^^
  File "C:\Users\Riccardo\miniconda3\envs\flower\Lib\site-packages\flwr\client\message_handler\message_handler.py", line 95, in handle_legacy_message_from_msgtype
    client = client_fn(context)
             ^^^^^^^^^^^^^^^^^^
  File "C:\Users\Riccardo\miniconda3\envs\flower\Lib\site-packages\flwr\client\client_app.py", line 67, in adaptor_fn
    return client_fn(str(cid))  # type: ignore
           ^^^^^^^^^^^^^^^^^^^
  File "c:\Users\Riccardo\Desktop\PoliMi\Tesi-Francesco\clients\multiclass\client_fedavg.py", line 120, in client_fn
    trainloader = trainloaders[int(cid)]
                  ~~~~~~~~~~~~^^^^^^^^^^
IndexError: list index out of range

The above exception was the direct cause of the following exception:

[36mray::ClientAppActor.run()[39m (pid=22472, ip=127.0.0.1, actor_id=c11cc626da41c49edd4531c801000000, repr=<flwr.simulation.ray_transport.ray_actor.ClientAppActor object at 0x000001F87F9A1050>)
  File "python\ray\_raylet.pyx", line 1853, in ray._raylet.execute_task
  File "python\ray\_raylet.pyx", line 1954, in ray._raylet.execute_task
  File "python\ray\_raylet.pyx", line 1859, in ray._raylet.execute_task
  File "python\ray\_raylet.pyx", line 1800, in ray._raylet.execute_task.function_executor
  File "C:\Users\Riccardo\miniconda3\envs\flower\Lib\site-packages\ray\_private\function_manager.py", line 696, in actor_method_executor
    return method(__ray_actor, *args, **kwargs)
           ^^^^^^^^^^^^^^^^^^^^^^^^^^^^^^^^^^^^
  File "C:\Users\Riccardo\miniconda3\envs\flower\Lib\site-packages\ray\util\tracing\tracing_helper.py", line 467, in _resume_span
    return method(self, *_args, **_kwargs)
           ^^^^^^^^^^^^^^^^^^^^^^^^^^^^^^^
  File "C:\Users\Riccardo\miniconda3\envs\flower\Lib\site-packages\flwr\simulation\ray_transport\ray_actor.py", line 63, in run
    raise ClientAppException(str(ex)) from ex
flwr.client.client_app.ClientAppException: 
Exception ClientAppException occurred. Message: list index out of range

[2025-01-28 17:31:29,879][flwr][ERROR] - [36mray::ClientAppActor.run()[39m (pid=22472, ip=127.0.0.1, actor_id=c11cc626da41c49edd4531c801000000, repr=<flwr.simulation.ray_transport.ray_actor.ClientAppActor object at 0x000001F87F9A1050>)
                  ^^^^^^^^^^^^^^^^^^^^^^^^^^^^^^^^^^^^^
  File "C:\Users\Riccardo\miniconda3\envs\flower\Lib\site-packages\flwr\client\client_app.py", line 143, in __call__
    return self._call(message, context)
           ^^^^^^^^^^^^^^^^^^^^^^^^^^^^
  File "C:\Users\Riccardo\miniconda3\envs\flower\Lib\site-packages\flwr\client\client_app.py", line 126, in ffn
    out_message = handle_legacy_message_from_msgtype(
                  ^^^^^^^^^^^^^^^^^^^^^^^^^^^^^^^^^^^
  File "C:\Users\Riccardo\miniconda3\envs\flower\Lib\site-packages\flwr\client\message_handler\message_handler.py", line 95, in handle_legacy_message_from_msgtype
    client = client_fn(context)
             ^^^^^^^^^^^^^^^^^^
  File "C:\Users\Riccardo\miniconda3\envs\flower\Lib\site-packages\flwr\client\client_app.py", line 67, in adaptor_fn
    return client_fn(str(cid))  # type: ignore
           ^^^^^^^^^^^^^^^^^^^
  File "c:\Users\Riccardo\Desktop\PoliMi\Tesi-Francesco\clients\multiclass\client_fedavg.py", line 120, in client_fn
    trainloader = trainloaders[int(cid)]
                  ~~~~~~~~~~~~^^^^^^^^^^
IndexError: list index out of range

The above exception was the direct cause of the following exception:

[36mray::ClientAppActor.run()[39m (pid=22472, ip=127.0.0.1, actor_id=c11cc626da41c49edd4531c801000000, repr=<flwr.simulation.ray_transport.ray_actor.ClientAppActor object at 0x000001F87F9A1050>)
  File "python\ray\_raylet.pyx", line 1853, in ray._raylet.execute_task
  File "python\ray\_raylet.pyx", line 1954, in ray._raylet.execute_task
  File "python\ray\_raylet.pyx", line 1859, in ray._raylet.execute_task
  File "python\ray\_raylet.pyx", line 1800, in ray._raylet.execute_task.function_executor
  File "C:\Users\Riccardo\miniconda3\envs\flower\Lib\site-packages\ray\_private\function_manager.py", line 696, in actor_method_executor
    return method(__ray_actor, *args, **kwargs)
           ^^^^^^^^^^^^^^^^^^^^^^^^^^^^^^^^^^^^
  File "C:\Users\Riccardo\miniconda3\envs\flower\Lib\site-packages\ray\util\tracing\tracing_helper.py", line 467, in _resume_span
    return method(self, *_args, **_kwargs)
           ^^^^^^^^^^^^^^^^^^^^^^^^^^^^^^^
  File "C:\Users\Riccardo\miniconda3\envs\flower\Lib\site-packages\flwr\simulation\ray_transport\ray_actor.py", line 63, in run
    raise ClientAppException(str(ex)) from ex
flwr.client.client_app.ClientAppException: 
Exception ClientAppException occurred. Message: list index out of range
